<robot name = "robot">
    <link name="Body1.0.0">
        <inertial>
            <origin xyz="0 0 5" rpy="0 0 0"/>
            <mass value="1" />
            <inertia ixx="100" ixy="0" ixz="0" iyy="100" iyz="0" izz="100" />
        </inertial>
        <visual>
            <origin xyz="0 0 5" rpy="0 0 0"/>
            <geometry>
                <box size="1.0208801302883965 0.6292807309003973 1.0128586628205736" />
            </geometry>
            <material name="Green">
                <color rgba="0.0 1.0 0.0 1.0"/>
            </material>
        </visual>
        <collision>
            <origin xyz="0 0 5" rpy="0 0 0"/>
            <geometry>
                <box size="1.0208801302883965 0.6292807309003973 1.0128586628205736" />
            </geometry>
        </collision>
    </link>
    <joint name="Body1.0.0_Body1.1.1" type="revolute">
       <parent link="Body1.0.0"/>
       <child  link="Body1.1.1"/>
       <origin rpy="0 0 0" xyz="0 0.31464036545019863 5" />
       <axis xyz="0 1 0"/>
       <limit effort="0.0" lower="-3.14159" upper="3.14159" velocity="0.0"/>
    </joint>
    <link name="Body1.1.1">
        <inertial>
            <origin xyz="0 0.36230225574035413 0" rpy="0 0 0"/>
            <mass value="1" />
            <inertia ixx="100" ixy="0" ixz="0" iyy="100" iyz="0" izz="100" />
        </inertial>
        <visual>
            <origin xyz="0 0.36230225574035413 0" rpy="0 0 0"/>
            <geometry>
                <box size="0.33067983538750617 0.7246045114807083 0.7110820054676577" />
            </geometry>
            <material name="Blue">
                <color rgba="0.0 0.0 1.0 1.0"/>
            </material>
        </visual>
        <collision>
            <origin xyz="0 0.36230225574035413 0" rpy="0 0 0"/>
            <geometry>
                <box size="0.33067983538750617 0.7246045114807083 0.7110820054676577" />
            </geometry>
        </collision>
    </link>
    <joint name="Body1.1.1_Body1.1.2" type="revolute">
       <parent link="Body1.1.1"/>
       <child  link="Body1.1.2"/>
       <origin rpy="0 0 0" xyz="0 0.7246045114807083 0" />
       <axis xyz="0 1 0"/>
       <limit effort="0.0" lower="-3.14159" upper="3.14159" velocity="0.0"/>
    </joint>
    <link name="Body1.1.2">
        <inertial>
            <origin xyz="0 0.2413614121416095 0" rpy="0 0 0"/>
            <mass value="1" />
            <inertia ixx="100" ixy="0" ixz="0" iyy="100" iyz="0" izz="100" />
        </inertial>
        <visual>
            <origin xyz="0 0.2413614121416095 0" rpy="0 0 0"/>
            <geometry>
                <box size="0.6211832703654394 0.482722824283219 0.7067515798947869" />
            </geometry>
            <material name="Blue">
                <color rgba="0.0 0.0 1.0 1.0"/>
            </material>
        </visual>
        <collision>
            <origin xyz="0 0.2413614121416095 0" rpy="0 0 0"/>
            <geometry>
                <box size="0.6211832703654394 0.482722824283219 0.7067515798947869" />
            </geometry>
        </collision>
    </link>
    <joint name="Body1.1.2_Body1.1.3" type="revolute">
       <parent link="Body1.1.2"/>
       <child  link="Body1.1.3"/>
       <origin rpy="0 0 0" xyz="0 0.2413614121416095 -0.35337578994739344" />
       <axis xyz="0 1 0"/>
       <limit effort="0.0" lower="-3.14159" upper="3.14159" velocity="0.0"/>
    </joint>
    <link name="Body1.1.3">
        <inertial>
            <origin xyz="0 0 -0.29632133413120565" rpy="0 0 0"/>
            <mass value="1" />
            <inertia ixx="100" ixy="0" ixz="0" iyy="100" iyz="0" izz="100" />
        </inertial>
        <visual>
            <origin xyz="0 0 -0.29632133413120565" rpy="0 0 0"/>
            <geometry>
                <box size="0.3718364543761921 0.5516477444780084 0.5926426682624113" />
            </geometry>
            <material name="Blue">
                <color rgba="0.0 0.0 1.0 1.0"/>
            </material>
        </visual>
        <collision>
            <origin xyz="0 0 -0.29632133413120565" rpy="0 0 0"/>
            <geometry>
                <box size="0.3718364543761921 0.5516477444780084 0.5926426682624113" />
            </geometry>
        </collision>
    </link>
    <joint name="Body1.1.3_Body1.1.4" type="revolute">
       <parent link="Body1.1.3"/>
       <child  link="Body1.1.4"/>
       <origin rpy="0 0 0" xyz="0 0 -0.5926426682624113" />
       <axis xyz="0 1 0"/>
       <limit effort="0.0" lower="-3.14159" upper="3.14159" velocity="0.0"/>
    </joint>
    <link name="Body1.1.4">
        <inertial>
            <origin xyz="0 0 -0.2770798759409097" rpy="0 0 0"/>
            <mass value="1" />
            <inertia ixx="100" ixy="0" ixz="0" iyy="100" iyz="0" izz="100" />
        </inertial>
        <visual>
            <origin xyz="0 0 -0.2770798759409097" rpy="0 0 0"/>
            <geometry>
                <box size="0.4952166833644836 0.7319734945576668 0.5541597518818194" />
            </geometry>
            <material name="Blue">
                <color rgba="0.0 0.0 1.0 1.0"/>
            </material>
        </visual>
        <collision>
            <origin xyz="0 0 -0.2770798759409097" rpy="0 0 0"/>
            <geometry>
                <box size="0.4952166833644836 0.7319734945576668 0.5541597518818194" />
            </geometry>
        </collision>
    </link>
    <joint name="Body1.0.0_Body1.2.1" type="revolute">
       <parent link="Body1.0.0"/>
       <child  link="Body1.2.1"/>
       <origin rpy="0 0 0" xyz="0 -0.31464036545019863 5" />
       <axis xyz="0 1 0"/>
       <limit effort="0.0" lower="-3.14159" upper="3.14159" velocity="0.0"/>
    </joint>
    <link name="Body1.2.1">
        <inertial>
            <origin xyz="0 -0.31659474937154436 0" rpy="0 0 0"/>
            <mass value="1" />
            <inertia ixx="100" ixy="0" ixz="0" iyy="100" iyz="0" izz="100" />
        </inertial>
        <visual>
            <origin xyz="0 -0.31659474937154436 0" rpy="0 0 0"/>
            <geometry>
                <box size="0.6273771900337952 0.6331894987430887 0.5218570098293982" />
            </geometry>
            <material name="Green">
                <color rgba="0.0 1.0 0.0 1.0"/>
            </material>
        </visual>
        <collision>
            <origin xyz="0 -0.31659474937154436 0" rpy="0 0 0"/>
            <geometry>
                <box size="0.6273771900337952 0.6331894987430887 0.5218570098293982" />
            </geometry>
        </collision>
    </link>
    <joint name="Body1.0.0_Body2.0.0" type="revolute">
       <parent link="Body1.0.0"/>
       <child  link="Body2.0.0"/>
       <origin rpy="0 0 0" xyz="0.5104400651441983 0 4.493570668589713" />
       <axis xyz="0 1 0"/>
       <limit effort="0.0" lower="-3.14159" upper="3.14159" velocity="0.0"/>
    </joint>
    <link name="Body2.0.0">
        <inertial>
            <origin xyz="0.624087682629496 0 0.5064293314102868" rpy="0 0 0"/>
            <mass value="1" />
            <inertia ixx="100" ixy="0" ixz="0" iyy="100" iyz="0" izz="100" />
        </inertial>
        <visual>
            <origin xyz="0.624087682629496 0 0.5064293314102868" rpy="0 0 0"/>
            <geometry>
                <box size="1.248175365258992 0.8364231942121284 0.9075987896531817" />
            </geometry>
            <material name="Green">
                <color rgba="0.0 1.0 0.0 1.0"/>
            </material>
        </visual>
        <collision>
            <origin xyz="0.624087682629496 0 0.5064293314102868" rpy="0 0 0"/>
            <geometry>
                <box size="1.248175365258992 0.8364231942121284 0.9075987896531817" />
            </geometry>
        </collision>
    </link>
    <joint name="Body2.0.0_Body2.1.1" type="revolute">
       <parent link="Body2.0.0"/>
       <child  link="Body2.1.1"/>
       <origin rpy="0 0 0" xyz="0.624087682629496 0.4182115971060642 0.5064293314102868" />
       <axis xyz="0 1 0"/>
       <limit effort="0.0" lower="-3.14159" upper="3.14159" velocity="0.0"/>
    </joint>
    <link name="Body2.1.1">
        <inertial>
            <origin xyz="0 0.2643119129992211 0" rpy="0 0 0"/>
            <mass value="1" />
            <inertia ixx="100" ixy="0" ixz="0" iyy="100" iyz="0" izz="100" />
        </inertial>
        <visual>
            <origin xyz="0 0.2643119129992211 0" rpy="0 0 0"/>
            <geometry>
                <box size="0.40100558991028695 0.5286238259984422 0.740020284101224" />
            </geometry>
            <material name="Green">
                <color rgba="0.0 1.0 0.0 1.0"/>
            </material>
        </visual>
        <collision>
            <origin xyz="0 0.2643119129992211 0" rpy="0 0 0"/>
            <geometry>
                <box size="0.40100558991028695 0.5286238259984422 0.740020284101224" />
            </geometry>
        </collision>
    </link>
    <joint name="Body2.0.0_Body2.2.1" type="revolute">
       <parent link="Body2.0.0"/>
       <child  link="Body2.2.1"/>
       <origin rpy="0 0 0" xyz="0.624087682629496 -0.4182115971060642 0.5064293314102868" />
       <axis xyz="0 1 0"/>
       <limit effort="0.0" lower="-3.14159" upper="3.14159" velocity="0.0"/>
    </joint>
    <link name="Body2.2.1">
        <inertial>
            <origin xyz="0 -0.3082538116320864 0" rpy="0 0 0"/>
            <mass value="1" />
            <inertia ixx="100" ixy="0" ixz="0" iyy="100" iyz="0" izz="100" />
        </inertial>
        <visual>
            <origin xyz="0 -0.3082538116320864 0" rpy="0 0 0"/>
            <geometry>
                <box size="0.4245264506929891 0.6165076232641729 0.6960630112380549" />
            </geometry>
            <material name="Blue">
                <color rgba="0.0 0.0 1.0 1.0"/>
            </material>
        </visual>
        <collision>
            <origin xyz="0 -0.3082538116320864 0" rpy="0 0 0"/>
            <geometry>
                <box size="0.4245264506929891 0.6165076232641729 0.6960630112380549" />
            </geometry>
        </collision>
    </link>
    <joint name="Body2.2.1_Body2.2.2" type="revolute">
       <parent link="Body2.2.1"/>
       <child  link="Body2.2.2"/>
       <origin rpy="0 0 0" xyz="0 -0.3082538116320864 -0.34803150561902746" />
       <axis xyz="0 1 0"/>
       <limit effort="0.0" lower="-3.14159" upper="3.14159" velocity="0.0"/>
    </joint>
    <link name="Body2.2.2">
        <inertial>
            <origin xyz="0 0 -0.3039945263167989" rpy="0 0 0"/>
            <mass value="1" />
            <inertia ixx="100" ixy="0" ixz="0" iyy="100" iyz="0" izz="100" />
        </inertial>
        <visual>
            <origin xyz="0 0 -0.3039945263167989" rpy="0 0 0"/>
            <geometry>
                <box size="0.6842540940940356 0.5954603163420473 0.6079890526335978" />
            </geometry>
            <material name="Green">
                <color rgba="0.0 1.0 0.0 1.0"/>
            </material>
        </visual>
        <collision>
            <origin xyz="0 0 -0.3039945263167989" rpy="0 0 0"/>
            <geometry>
                <box size="0.6842540940940356 0.5954603163420473 0.6079890526335978" />
            </geometry>
        </collision>
    </link>
    <joint name="Body2.2.2_Body2.2.3" type="revolute">
       <parent link="Body2.2.2"/>
       <child  link="Body2.2.3"/>
       <origin rpy="0 0 0" xyz="0 -0.29773015817102366 -0.3039945263167989" />
       <axis xyz="0 1 0"/>
       <limit effort="0.0" lower="-3.14159" upper="3.14159" velocity="0.0"/>
    </joint>
    <link name="Body2.2.3">
        <inertial>
            <origin xyz="0 -0.22108459970051333 0" rpy="0 0 0"/>
            <mass value="1" />
            <inertia ixx="100" ixy="0" ixz="0" iyy="100" iyz="0" izz="100" />
        </inertial>
        <visual>
            <origin xyz="0 -0.22108459970051333 0" rpy="0 0 0"/>
            <geometry>
                <box size="0.41952372036598684 0.44216919940102667 0.5934406849350687" />
            </geometry>
            <material name="Green">
                <color rgba="0.0 1.0 0.0 1.0"/>
            </material>
        </visual>
        <collision>
            <origin xyz="0 -0.22108459970051333 0" rpy="0 0 0"/>
            <geometry>
                <box size="0.41952372036598684 0.44216919940102667 0.5934406849350687" />
            </geometry>
        </collision>
    </link>
    <joint name="Body2.0.0_Body3.0.0" type="revolute">
       <parent link="Body2.0.0"/>
       <child  link="Body3.0.0"/>
       <origin rpy="0 0 0" xyz="1.248175365258992 0 0.5064293314102868" />
       <axis xyz="0 1 0"/>
       <limit effort="0.0" lower="-3.14159" upper="3.14159" velocity="0.0"/>
    </joint>
    <link name="Body3.0.0">
        <inertial>
            <origin xyz="0.6107538832000919 0 0" rpy="0 0 0"/>
            <mass value="1" />
            <inertia ixx="100" ixy="0" ixz="0" iyy="100" iyz="0" izz="100" />
        </inertial>
        <visual>
            <origin xyz="0.6107538832000919 0 0" rpy="0 0 0"/>
            <geometry>
                <box size="1.2215077664001839 1.1211363178593043 0.6607859408886302" />
            </geometry>
            <material name="Blue">
                <color rgba="0.0 0.0 1.0 1.0"/>
            </material>
        </visual>
        <collision>
            <origin xyz="0.6107538832000919 0 0" rpy="0 0 0"/>
            <geometry>
                <box size="1.2215077664001839 1.1211363178593043 0.6607859408886302" />
            </geometry>
        </collision>
    </link>
    <joint name="Body3.0.0_Body3.1.1" type="revolute">
       <parent link="Body3.0.0"/>
       <child  link="Body3.1.1"/>
       <origin rpy="0 0 0" xyz="0.6107538832000919 0.5605681589296522 0" />
       <axis xyz="0 1 0"/>
       <limit effort="0.0" lower="-3.14159" upper="3.14159" velocity="0.0"/>
    </joint>
    <link name="Body3.1.1">
        <inertial>
            <origin xyz="0 0.13604378238758177 0" rpy="0 0 0"/>
            <mass value="1" />
            <inertia ixx="100" ixy="0" ixz="0" iyy="100" iyz="0" izz="100" />
        </inertial>
        <visual>
            <origin xyz="0 0.13604378238758177 0" rpy="0 0 0"/>
            <geometry>
                <box size="0.3825567431094308 0.27208756477516355 0.7328585291113722" />
            </geometry>
            <material name="Blue">
                <color rgba="0.0 0.0 1.0 1.0"/>
            </material>
        </visual>
        <collision>
            <origin xyz="0 0.13604378238758177 0" rpy="0 0 0"/>
            <geometry>
                <box size="0.3825567431094308 0.27208756477516355 0.7328585291113722" />
            </geometry>
        </collision>
    </link>
    <joint name="Body3.1.1_Body3.1.2" type="revolute">
       <parent link="Body3.1.1"/>
       <child  link="Body3.1.2"/>
       <origin rpy="0 0 0" xyz="0 0.13604378238758177 -0.3664292645556861" />
       <axis xyz="0 1 0"/>
       <limit effort="0.0" lower="-3.14159" upper="3.14159" velocity="0.0"/>
    </joint>
    <link name="Body3.1.2">
        <inertial>
            <origin xyz="0 0 -0.27295823072752623" rpy="0 0 0"/>
            <mass value="1" />
            <inertia ixx="100" ixy="0" ixz="0" iyy="100" iyz="0" izz="100" />
        </inertial>
        <visual>
            <origin xyz="0 0 -0.27295823072752623" rpy="0 0 0"/>
            <geometry>
                <box size="0.27964403070031496 0.44546765620636763 0.5459164614550525" />
            </geometry>
            <material name="Green">
                <color rgba="0.0 1.0 0.0 1.0"/>
            </material>
        </visual>
        <collision>
            <origin xyz="0 0 -0.27295823072752623" rpy="0 0 0"/>
            <geometry>
                <box size="0.27964403070031496 0.44546765620636763 0.5459164614550525" />
            </geometry>
        </collision>
    </link>
    <joint name="Body3.1.2_Body3.1.3" type="revolute">
       <parent link="Body3.1.2"/>
       <child  link="Body3.1.3"/>
       <origin rpy="0 0 0" xyz="0 0.22273382810318382 -0.27295823072752623" />
       <axis xyz="0 1 0"/>
       <limit effort="0.0" lower="-3.14159" upper="3.14159" velocity="0.0"/>
    </joint>
    <link name="Body3.1.3">
        <inertial>
            <origin xyz="0 0.3603142007074686 0" rpy="0 0 0"/>
            <mass value="1" />
            <inertia ixx="100" ixy="0" ixz="0" iyy="100" iyz="0" izz="100" />
        </inertial>
        <visual>
            <origin xyz="0 0.3603142007074686 0" rpy="0 0 0"/>
            <geometry>
                <box size="0.3484657036883442 0.7206284014149372 0.6089668933589294" />
            </geometry>
            <material name="Green">
                <color rgba="0.0 1.0 0.0 1.0"/>
            </material>
        </visual>
        <collision>
            <origin xyz="0 0.3603142007074686 0" rpy="0 0 0"/>
            <geometry>
                <box size="0.3484657036883442 0.7206284014149372 0.6089668933589294" />
            </geometry>
        </collision>
    </link>
    <joint name="Body3.0.0_Body3.2.1" type="revolute">
       <parent link="Body3.0.0"/>
       <child  link="Body3.2.1"/>
       <origin rpy="0 0 0" xyz="0.6107538832000919 -0.5605681589296522 0" />
       <axis xyz="0 1 0"/>
       <limit effort="0.0" lower="-3.14159" upper="3.14159" velocity="0.0"/>
    </joint>
    <link name="Body3.2.1">
        <inertial>
            <origin xyz="0 -0.33256451838316614 0" rpy="0 0 0"/>
            <mass value="1" />
            <inertia ixx="100" ixy="0" ixz="0" iyy="100" iyz="0" izz="100" />
        </inertial>
        <visual>
            <origin xyz="0 -0.33256451838316614 0" rpy="0 0 0"/>
            <geometry>
                <box size="0.5668598589381768 0.6651290367663323 0.6308806293130266" />
            </geometry>
            <material name="Green">
                <color rgba="0.0 1.0 0.0 1.0"/>
            </material>
        </visual>
        <collision>
            <origin xyz="0 -0.33256451838316614 0" rpy="0 0 0"/>
            <geometry>
                <box size="0.5668598589381768 0.6651290367663323 0.6308806293130266" />
            </geometry>
        </collision>
    </link>
    <joint name="Body3.2.1_Body3.2.2" type="revolute">
       <parent link="Body3.2.1"/>
       <child  link="Body3.2.2"/>
       <origin rpy="0 0 0" xyz="0 -0.6651290367663323 0" />
       <axis xyz="0 1 0"/>
       <limit effort="0.0" lower="-3.14159" upper="3.14159" velocity="0.0"/>
    </joint>
    <link name="Body3.2.2">
        <inertial>
            <origin xyz="0 -0.3177054173376243 0" rpy="0 0 0"/>
            <mass value="1" />
            <inertia ixx="100" ixy="0" ixz="0" iyy="100" iyz="0" izz="100" />
        </inertial>
        <visual>
            <origin xyz="0 -0.3177054173376243 0" rpy="0 0 0"/>
            <geometry>
                <box size="0.659730242017804 0.6354108346752486 0.6512199917280578" />
            </geometry>
            <material name="Blue">
                <color rgba="0.0 0.0 1.0 1.0"/>
            </material>
        </visual>
        <collision>
            <origin xyz="0 -0.3177054173376243 0" rpy="0 0 0"/>
            <geometry>
                <box size="0.659730242017804 0.6354108346752486 0.6512199917280578" />
            </geometry>
        </collision>
    </link>
    <joint name="Body3.2.2_Body3.2.3" type="revolute">
       <parent link="Body3.2.2"/>
       <child  link="Body3.2.3"/>
       <origin rpy="0 0 0" xyz="0 -0.3177054173376243 -0.3256099958640289" />
       <axis xyz="0 1 0"/>
       <limit effort="0.0" lower="-3.14159" upper="3.14159" velocity="0.0"/>
    </joint>
    <link name="Body3.2.3">
        <inertial>
            <origin xyz="0 0 -0.33446239676774703" rpy="0 0 0"/>
            <mass value="1" />
            <inertia ixx="100" ixy="0" ixz="0" iyy="100" iyz="0" izz="100" />
        </inertial>
        <visual>
            <origin xyz="0 0 -0.33446239676774703" rpy="0 0 0"/>
            <geometry>
                <box size="0.5317515986264261 0.6935438008763658 0.6689247935354941" />
            </geometry>
            <material name="Green">
                <color rgba="0.0 1.0 0.0 1.0"/>
            </material>
        </visual>
        <collision>
            <origin xyz="0 0 -0.33446239676774703" rpy="0 0 0"/>
            <geometry>
                <box size="0.5317515986264261 0.6935438008763658 0.6689247935354941" />
            </geometry>
        </collision>
    </link>
</robot>